Workbook

Sheet Dashboard
A2: 🛡️ INSURANCE POLICY RENEWAL TRACKER | G2: ="Live as of "&TEXT(TODAY(),"d mmmm yyyy")&" · Policies: "&COUNTA('Policy Register'!C5:C304)
A3: Your Brokerage Name · Never let a renewal slip through the cracks
B5: TOTAL POLICIES | D5: ✅ RENEWED | H5: 📅 DUE IN 30 DAYS | J5: 🚨 OVERDUE
B6: =COUNTA('Policy Register'!C5:C304) | D6: =COUNTIF('Policy Register'!G5:G304,"Renewed") | H6: =COUNTIFS('Policy Register'!G5:G304,"<>Renewed",'Policy Register'!F5:F304,">="&TODAY(),'Policy Register'!F5:F304,"<="&(TODAY()+30)) | J6: =COUNTIF('Policy Register'!H5:H304,">0")
B7: "Active book of business" | D7: =IFERROR(TEXT(COUNTIF('Policy Register'!G5:G304,"Renewed")/COUNTA('Policy Register'!C5:C304),"0%")&" of book","") | H7: "Plan outreach now" | J7: "Needs immediate attention"
B9: DUE IN 60 DAYS | D9: DUE IN 14 DAYS | H9: DUE IN 7 DAYS | J9: 📅 DUE TODAY
B10: =COUNTIFS('Policy Register'!G5:G304,"<>Renewed",'Policy Register'!F5:F304,">="&TODAY(),'Policy Register'!F5:F304,"<="&(TODAY()+60)) | D10: =COUNTIFS('Policy Register'!G5:G304,"<>Renewed",'Policy Register'!F5:F304,">="&TODAY(),'Policy Register'!F5:F304,"<="&(TODAY()+14)) | H10: =COUNTIFS('Policy Register'!G5:G304,"<>Renewed",'Policy Register'!F5:F304,">="&TODAY(),'Policy Register'!F5:F304,"<="&(TODAY()+7)) | J10: =COUNTIFS('Policy Register'!G5:G304,"<>Renewed",'Policy Register'!F5:F304,TODAY())
B11: "Early notice window" | D11: "Confirm client contact" | H11: "This week" | J11: "Action required today"
B13: 📅 UPCOMING RENEWALS — Soonest due first | H13: 🚨 OVERDUE POLICIES — Requires action
B14: CLIENT | C14: CLASS | D14: DUE DATE | E14: STATUS | H14: CLIENT | I14: CLASS | J14: DAYS LATE | K14: STATUS
B15: =IFERROR(INDEX('Policy Register'!$C:$C,MATCH(1,'Policy Register'!$L:$L,0)),"") | C15: =IFERROR(INDEX('Policy Register'!$D:$D,MATCH(1,'Policy Register'!$L:$L,0)),"") | D15: =IFERROR(INDEX('Policy Register'!$F:$F,MATCH(1,'Policy Register'!$L:$L,0)),"") | E15: =IFERROR(INDEX('Policy Register'!$G:$G,MATCH(1,'Policy Register'!$L:$L,0)),"") | H15: =IFERROR(INDEX('Policy Register'!$C:$C,MATCH(1,'Policy Register'!$M:$M,0)),"") | I15: =IFERROR(INDEX('Policy Register'!$D:$D,MATCH(1,'Policy Register'!$M:$M,0)),"") | J15: =IFERROR(INDEX('Policy Register'!$H:$H,MATCH(1,'Policy Register'!$M:$M,0)),"") | K15: =IFERROR(INDEX('Policy Register'!$G:$G,MATCH(1,'Policy Register'!$M:$M,0)),"")
B16: =IFERROR(INDEX('Policy Register'!$C:$C,MATCH(2,'Policy Register'!$L:$L,0)),"") | C16: =IFERROR(INDEX('Policy Register'!$D:$D,MATCH(2,'Policy Register'!$L:$L,0)),"") | D16: =IFERROR(INDEX('Policy Register'!$F:$F,MATCH(2,'Policy Register'!$L:$L,0)),"") | E16: =IFERROR(INDEX('Policy Register'!$G:$G,MATCH(2,'Policy Register'!$L:$L,0)),"") | H16: =IFERROR(INDEX('Policy Register'!$C:$C,MATCH(2,'Policy Register'!$M:$M,0)),"") | I16: =IFERROR(INDEX('Policy Register'!$D:$D,MATCH(2,'Policy Register'!$M:$M,0)),"") | J16: =IFERROR(INDEX('Policy Register'!$H:$H,MATCH(2,'Policy Register'!$M:$M,0)),"") | K16: =IFERROR(INDEX('Policy Register'!$G:$G,MATCH(2,'Policy Register'!$M:$M,0)),"")
B17: =IFERROR(INDEX('Policy Register'!$C:$C,MATCH(3,'Policy Register'!$L:$L,0)),"") | C17: =IFERROR(INDEX('Policy Register'!$D:$D,MATCH(3,'Policy Register'!$L:$L,0)),"") | D17: =IFERROR(INDEX('Policy Register'!$F:$F,MATCH(3,'Policy Register'!$L:$L,0)),"") | E17: =IFERROR(INDEX('Policy Register'!$G:$G,MATCH(3,'Policy Register'!$L:$L,0)),"") | H17: =IFERROR(INDEX('Policy Register'!$C:$C,MATCH(3,'Policy Register'!$M:$M,0)),"") | I17: =IFERROR(INDEX('Policy Register'!$D:$D,MATCH(3,'Policy Register'!$M:$M,0)),"") | J17: =IFERROR(INDEX('Policy Register'!$H:$H,MATCH(3,'Policy Register'!$M:$M,0)),"") | K17: =IFERROR(INDEX('Policy Register'!$G:$G,MATCH(3,'Policy Register'!$M:$M,0)),"")
B18: =IFERROR(INDEX('Policy Register'!$C:$C,MATCH(4,'Policy Register'!$L:$L,0)),"") | C18: =IFERROR(INDEX('Policy Register'!$D:$D,MATCH(4,'Policy Register'!$L:$L,0)),"") | D18: =IFERROR(INDEX('Policy Register'!$F:$F,MATCH(4,'Policy Register'!$L:$L,0)),"") | E18: =IFERROR(INDEX('Policy Register'!$G:$G,MATCH(4,'Policy Register'!$L:$L,0)),"") | H18: =IFERROR(INDEX('Policy Register'!$C:$C,MATCH(4,'Policy Register'!$M:$M,0)),"") | I18: =IFERROR(INDEX('Policy Register'!$D:$D,MATCH(4,'Policy Register'!$M:$M,0)),"") | J18: =IFERROR(INDEX('Policy Register'!$H:$H,MATCH(4,'Policy Register'!$M:$M,0)),"") | K18: =IFERROR(INDEX('Policy Register'!$G:$G,MATCH(4,'Policy Register'!$M:$M,0)),"")
B19: =IFERROR(INDEX('Policy Register'!$C:$C,MATCH(5,'Policy Register'!$L:$L,0)),"") | C19: =IFERROR(INDEX('Policy Register'!$D:$D,MATCH(5,'Policy Register'!$L:$L,0)),"") | D19: =IFERROR(INDEX('Policy Register'!$F:$F,MATCH(5,'Policy Register'!$L:$L,0)),"") | E19: =IFERROR(INDEX('Policy Register'!$G:$G,MATCH(5,'Policy Register'!$L:$L,0)),"") | H19: =IFERROR(INDEX('Policy Register'!$C:$C,MATCH(5,'Policy Register'!$M:$M,0)),"") | I19: =IFERROR(INDEX('Policy Register'!$D:$D,MATCH(5,'Policy Register'!$M:$M,0)),"") | J19: =IFERROR(INDEX('Policy Register'!$H:$H,MATCH(5,'Policy Register'!$M:$M,0)),"") | K19: =IFERROR(INDEX('Policy Register'!$G:$G,MATCH(5,'Policy Register'!$M:$M,0)),"")
B20: =IFERROR(INDEX('Policy Register'!$C:$C,MATCH(6,'Policy Register'!$L:$L,0)),"") | C20: =IFERROR(INDEX('Policy Register'!$D:$D,MATCH(6,'Policy Register'!$L:$L,0)),"") | D20: =IFERROR(INDEX('Policy Register'!$F:$F,MATCH(6,'Policy Register'!$L:$L,0)),"") | E20: =IFERROR(INDEX('Policy Register'!$G:$G,MATCH(6,'Policy Register'!$L:$L,0)),"") | H20: =IFERROR(INDEX('Policy Register'!$C:$C,MATCH(6,'Policy Register'!$M:$M,0)),"") | I20: =IFERROR(INDEX('Policy Register'!$D:$D,MATCH(6,'Policy Register'!$M:$M,0)),"") | J20: =IFERROR(INDEX('Policy Register'!$H:$H,MATCH(6,'Policy Register'!$M:$M,0)),"") | K20: =IFERROR(INDEX('Policy Register'!$G:$G,MATCH(6,'Policy Register'!$M:$M,0)),"")
B21: =IFERROR(INDEX('Policy Register'!$C:$C,MATCH(7,'Policy Register'!$L:$L,0)),"") | C21: =IFERROR(INDEX('Policy Register'!$D:$D,MATCH(7,'Policy Register'!$L:$L,0)),"") | D21: =IFERROR(INDEX('Policy Register'!$F:$F,MATCH(7,'Policy Register'!$L:$L,0)),"") | E21: =IFERROR(INDEX('Policy Register'!$G:$G,MATCH(7,'Policy Register'!$L:$L,0)),"") | H21: =IFERROR(INDEX('Policy Register'!$C:$C,MATCH(7,'Policy Register'!$M:$M,0)),"") | I21: =IFERROR(INDEX('Policy Register'!$D:$D,MATCH(7,'Policy Register'!$M:$M,0)),"") | J21: =IFERROR(INDEX('Policy Register'!$H:$H,MATCH(7,'Policy Register'!$M:$M,0)),"") | K21: =IFERROR(INDEX('Policy Register'!$G:$G,MATCH(7,'Policy Register'!$M:$M,0)),"")
B22: =IFERROR(INDEX('Policy Register'!$C:$C,MATCH(8,'Policy Register'!$L:$L,0)),"") | C22: =IFERROR(INDEX('Policy Register'!$D:$D,MATCH(8,'Policy Register'!$L:$L,0)),"") | D22: =IFERROR(INDEX('Policy Register'!$F:$F,MATCH(8,'Policy Register'!$L:$L,0)),"") | E22: =IFERROR(INDEX('Policy Register'!$G:$G,MATCH(8,'Policy Register'!$L:$L,0)),"") | H22: =IFERROR(INDEX('Policy Register'!$C:$C,MATCH(8,'Policy Register'!$M:$M,0)),"") | I22: =IFERROR(INDEX('Policy Register'!$D:$D,MATCH(8,'Policy Register'!$M:$M,0)),"") | J22: =IFERROR(INDEX('Policy Register'!$H:$H,MATCH(8,'Policy Register'!$M:$M,0)),"") | K22: =IFERROR(INDEX('Policy Register'!$G:$G,MATCH(8,'Policy Register'!$M:$M,0)),"")
B23: =IFERROR(INDEX('Policy Register'!$C:$C,MATCH(9,'Policy Register'!$L:$L,0)),"") | C23: =IFERROR(INDEX('Policy Register'!$D:$D,MATCH(9,'Policy Register'!$L:$L,0)),"") | D23: =IFERROR(INDEX('Policy Register'!$F:$F,MATCH(9,'Policy Register'!$L:$L,0)),"") | E23: =IFERROR(INDEX('Policy Register'!$G:$G,MATCH(9,'Policy Register'!$L:$L,0)),"") | H23: =IFERROR(INDEX('Policy Register'!$C:$C,MATCH(9,'Policy Register'!$M:$M,0)),"") | I23: =IFERROR(INDEX('Policy Register'!$D:$D,MATCH(9,'Policy Register'!$M:$M,0)),"") | J23: =IFERROR(INDEX('Policy Register'!$H:$H,MATCH(9,'Policy Register'!$M:$M,0)),"") | K23: =IFERROR(INDEX('Policy Register'!$G:$G,MATCH(9,'Policy Register'!$M:$M,0)),"")
B24: =IFERROR(INDEX('Policy Register'!$C:$C,MATCH(10,'Policy Register'!$L:$L,0)),"") | C24: =IFERROR(INDEX('Policy Register'!$D:$D,MATCH(10,'Policy Register'!$L:$L,0)),"") | D24: =IFERROR(INDEX('Policy Register'!$F:$F,MATCH(10,'Policy Register'!$L:$L,0)),"") | E24: =IFERROR(INDEX('Policy Register'!$G:$G,MATCH(10,'Policy Register'!$L:$L,0)),"") | H24: =IFERROR(INDEX('Policy Register'!$C:$C,MATCH(10,'Policy Register'!$M:$M,0)),"") | I24: =IFERROR(INDEX('Policy Register'!$D:$D,MATCH(10,'Policy Register'!$M:$M,0)),"") | J24: =IFERROR(INDEX('Policy Register'!$H:$H,MATCH(10,'Policy Register'!$M:$M,0)),"") | K24: =IFERROR(INDEX('Policy Register'!$G:$G,MATCH(10,'Policy Register'!$M:$M,0)),"")

Sheet Weekly Renewals
A2: 📅 WEEKLY RENEWALS — This week's operational view
A3: Refreshes automatically · Policies grouped by due date, Monday through Sunday
A5: =TODAY()-WEEKDAY(TODAY(),3)
B6: ="📅 " & "MONDAY" & " · " & TEXT(A5+0,"d mmm yyyy")
B7: =IF(COUNTIFS('Policy Register'!$F$5:$F$304,A5+0)=0,"No renewals scheduled.","")
B8: CLIENT | C8: CLASS | D8: DESCRIPTION | E8: DUE DATE | F8: STATUS
B9: =IFERROR(INDEX('Policy Register'!$C:$C,MATCH(TEXT(A5+0,"yyyymmdd")&"-"&1,'Policy Register'!$O:$O,0)),"") | C9: =IFERROR(INDEX('Policy Register'!$D:$D,MATCH(TEXT(A5+0,"yyyymmdd")&"-"&1,'Policy Register'!$O:$O,0)),"") | D9: =IFERROR(INDEX('Policy Register'!$E:$E,MATCH(TEXT(A5+0,"yyyymmdd")&"-"&1,'Policy Register'!$O:$O,0)),"") | E9: =IFERROR(INDEX('Policy Register'!$F:$F,MATCH(TEXT(A5+0,"yyyymmdd")&"-"&1,'Policy Register'!$O:$O,0)),"") | F9: =IFERROR(INDEX('Policy Register'!$G:$G,MATCH(TEXT(A5+0,"yyyymmdd")&"-"&1,'Policy Register'!$O:$O,0)),"")
B10: =IFERROR(INDEX('Policy Register'!$C:$C,MATCH(TEXT(A5+0,"yyyymmdd")&"-"&2,'Policy Register'!$O:$O,0)),"") | C10: =IFERROR(INDEX('Policy Register'!$D:$D,MATCH(TEXT(A5+0,"yyyymmdd")&"-"&2,'Policy Register'!$O:$O,0)),"") | D10: =IFERROR(INDEX('Policy Register'!$E:$E,MATCH(TEXT(A5+0,"yyyymmdd")&"-"&2,'Policy Register'!$O:$O,0)),"") | E10: =IFERROR(INDEX('Policy Register'!$F:$F,MATCH(TEXT(A5+0,"yyyymmdd")&"-"&2,'Policy Register'!$O:$O,0)),"") | F10: =IFERROR(INDEX('Policy Register'!$G:$G,MATCH(TEXT(A5+0,"yyyymmdd")&"-"&2,'Policy Register'!$O:$O,0)),"")
B11: =IFERROR(INDEX('Policy Register'!$C:$C,MATCH(TEXT(A5+0,"yyyymmdd")&"-"&3,'Policy Register'!$O:$O,0)),"") | C11: =IFERROR(INDEX('Policy Register'!$D:$D,MATCH(TEXT(A5+0,"yyyymmdd")&"-"&3,'Policy Register'!$O:$O,0)),"") | D11: =IFERROR(INDEX('Policy Register'!$E:$E,MATCH(TEXT(A5+0,"yyyymmdd")&"-"&3,'Policy Register'!$O:$O,0)),"") | E11: =IFERROR(INDEX('Policy Register'!$F:$F,MATCH(TEXT(A5+0,"yyyymmdd")&"-"&3,'Policy Register'!$O:$O,0)),"") | F11: =IFERROR(INDEX('Policy Register'!$G:$G,MATCH(TEXT(A5+0,"yyyymmdd")&"-"&3,'Policy Register'!$O:$O,0)),"")
B12: =IFERROR(INDEX('Policy Register'!$C:$C,MATCH(TEXT(A5+0,"yyyymmdd")&"-"&4,'Policy Register'!$O:$O,0)),"") | C12: =IFERROR(INDEX('Policy Register'!$D:$D,MATCH(TEXT(A5+0,"yyyymmdd")&"-"&4,'Policy Register'!$O:$O,0)),"") | D12: =IFERROR(INDEX('Policy Register'!$E:$E,MATCH(TEXT(A5+0,"yyyymmdd")&"-"&4,'Policy Register'!$O:$O,0)),"") | E12: =IFERROR(INDEX('Policy Register'!$F:$F,MATCH(TEXT(A5+0,"yyyymmdd")&"-"&4,'Policy Register'!$O:$O,0)),"") | F12: =IFERROR(INDEX('Policy Register'!$G:$G,MATCH(TEXT(A5+0,"yyyymmdd")&"-"&4,'Policy Register'!$O:$O,0)),"")
B14: ="📅 " & "TUESDAY" & " · " & TEXT(A5+1,"d mmm yyyy")
B15: =IF(COUNTIFS('Policy Register'!$F$5:$F$304,A5+1)=0,"No renewals scheduled.","")
B16: CLIENT | C16: CLASS | D16: DESCRIPTION | E16: DUE DATE | F16: STATUS
B17: =IFERROR(INDEX('Policy Register'!$C:$C,MATCH(TEXT(A5+1,"yyyymmdd")&"-"&1,'Policy Register'!$O:$O,0)),"") | C17: =IFERROR(INDEX('Policy Register'!$D:$D,MATCH(TEXT(A5+1,"yyyymmdd")&"-"&1,'Policy Register'!$O:$O,0)),"") | D17: =IFERROR(INDEX('Policy Register'!$E:$E,MATCH(TEXT(A5+1,"yyyymmdd")&"-"&1,'Policy Register'!$O:$O,0)),"") | E17: =IFERROR(INDEX('Policy Register'!$F:$F,MATCH(TEXT(A5+1,"yyyymmdd")&"-"&1,'Policy Register'!$O:$O,0)),"") | F17: =IFERROR(INDEX('Policy Register'!$G:$G,MATCH(TEXT(A5+1,"yyyymmdd")&"-"&1,'Policy Register'!$O:$O,0)),"")
B18: =IFERROR(INDEX('Policy Register'!$C:$C,MATCH(TEXT(A5+1,"yyyymmdd")&"-"&2,'Policy Register'!$O:$O,0)),"") | C18: =IFERROR(INDEX('Policy Register'!$D:$D,MATCH(TEXT(A5+1,"yyyymmdd")&"-"&2,'Policy Register'!$O:$O,0)),"") | D18: =IFERROR(INDEX('Policy Register'!$E:$E,MATCH(TEXT(A5+1,"yyyymmdd")&"-"&2,'Policy Register'!$O:$O,0)),"") | E18: =IFERROR(INDEX('Policy Register'!$F:$F,MATCH(TEXT(A5+1,"yyyymmdd")&"-"&2,'Policy Register'!$O:$O,0)),"") | F18: =IFERROR(INDEX('Policy Register'!$G:$G,MATCH(TEXT(A5+1,"yyyymmdd")&"-"&2,'Policy Register'!$O:$O,0)),"")
B19: =IFERROR(INDEX('Policy Register'!$C:$C,MATCH(TEXT(A5+1,"yyyymmdd")&"-"&3,'Policy Register'!$O:$O,0)),"") | C19: =IFERROR(INDEX('Policy Register'!$D:$D,MATCH(TEXT(A5+1,"yyyymmdd")&"-"&3,'Policy Register'!$O:$O,0)),"") | D19: =IFERROR(INDEX('Policy Register'!$E:$E,MATCH(TEXT(A5+1,"yyyymmdd")&"-"&3,'Policy Register'!$O:$O,0)),"") | E19: =IFERROR(INDEX('Policy Register'!$F:$F,MATCH(TEXT(A5+1,"yyyymmdd")&"-"&3,'Policy Register'!$O:$O,0)),"") | F19: =IFERROR(INDEX('Policy Register'!$G:$G,MATCH(TEXT(A5+1,"yyyymmdd")&"-"&3,'Policy Register'!$O:$O,0)),"")
B20: =IFERROR(INDEX('Policy Register'!$C:$C,MATCH(TEXT(A5+1,"yyyymmdd")&"-"&4,'Policy Register'!$O:$O,0)),"") | C20: =IFERROR(INDEX('Policy Register'!$D:$D,MATCH(TEXT(A5+1,"yyyymmdd")&"-"&4,'Policy Register'!$O:$O,0)),"") | D20: =IFERROR(INDEX('Policy Register'!$E:$E,MATCH(TEXT(A5+1,"yyyymmdd")&"-"&4,'Policy Register'!$O:$O,0)),"") | E20: =IFERROR(INDEX('Policy Register'!$F:$F,MATCH(TEXT(A5+1,"yyyymmdd")&"-"&4,'Policy Register'!$O:$O,0)),"") | F20: =IFERROR(INDEX('Policy Register'!$G:$G,MATCH(TEXT(A5+1,"yyyymmdd")&"-"&4,'Policy Register'!$O:$O,0)),"")
B22: ="📅 " & "WEDNESDAY" & " · " & TEXT(A5+2,"d mmm yyyy")
B23: =IF(COUNTIFS('Policy Register'!$F$5:$F$304,A5+2)=0,"No renewals scheduled.","")
B24: CLIENT | C24: CLASS | D24: DESCRIPTION | E24: DUE DATE | F24: STATUS
B25: =IFERROR(INDEX('Policy Register'!$C:$C,MATCH(TEXT(A5+2,"yyyymmdd")&"-"&1,'Policy Register'!$O:$O,0)),"") | C25: =IFERROR(INDEX('Policy Register'!$D:$D,MATCH(TEXT(A5+2,"yyyymmdd")&"-"&1,'Policy Register'!$O:$O,0)),"") | D25: =IFERROR(INDEX('Policy Register'!$E:$E,MATCH(TEXT(A5+2,"yyyymmdd")&"-"&1,'Policy Register'!$O:$O,0)),"") | E25: =IFERROR(INDEX('Policy Register'!$F:$F,MATCH(TEXT(A5+2,"yyyymmdd")&"-"&1,'Policy Register'!$O:$O,0)),"") | F25: =IFERROR(INDEX('Policy Register'!$G:$G,MATCH(TEXT(A5+2,"yyyymmdd")&"-"&1,'Policy Register'!$O:$O,0)),"")
B26: =IFERROR(INDEX('Policy Register'!$C:$C,MATCH(TEXT(A5+2,"yyyymmdd")&"-"&2,'Policy Register'!$O:$O,0)),"") | C26: =IFERROR(INDEX('Policy Register'!$D:$D,MATCH(TEXT(A5+2,"yyyymmdd")&"-"&2,'Policy Register'!$O:$O,0)),"") | D26: =IFERROR(INDEX('Policy Register'!$E:$E,MATCH(TEXT(A5+2,"yyyymmdd")&"-"&2,'Policy Register'!$O:$O,0)),"") | E26: =IFERROR(INDEX('Policy Register'!$F:$F,MATCH(TEXT(A5+2,"yyyymmdd")&"-"&2,'Policy Register'!$O:$O,0)),"") | F26: =IFERROR(INDEX('Policy Register'!$G:$G,MATCH(TEXT(A5+2,"yyyymmdd")&"-"&2,'Policy Register'!$O:$O,0)),"")
B27: =IFERROR(INDEX('Policy Register'!$C:$C,MATCH(TEXT(A5+2,"yyyymmdd")&"-"&3,'Policy Register'!$O:$O,0)),"") | C27: =IFERROR(INDEX('Policy Register'!$D:$D,MATCH(TEXT(A5+2,"yyyymmdd")&"-"&3,'Policy Register'!$O:$O,0)),"") | D27: =IFERROR(INDEX('Policy Register'!$E:$E,MATCH(TEXT(A5+2,"yyyymmdd")&"-"&3,'Policy Register'!$O:$O,0)),"") | E27: =IFERROR(INDEX('Policy Register'!$F:$F,MATCH(TEXT(A5+2,"yyyymmdd")&"-"&3,'Policy Register'!$O:$O,0)),"") | F27: =IFERROR(INDEX('Policy Register'!$G:$G,MATCH(TEXT(A5+2,"yyyymmdd")&"-"&3,'Policy Register'!$O:$O,0)),"")
B28: =IFERROR(INDEX('Policy Register'!$C:$C,MATCH(TEXT(A5+2,"yyyymmdd")&"-"&4,'Policy Register'!$O:$O,0)),"") | C28: =IFERROR(INDEX('Policy Register'!$D:$D,MATCH(TEXT(A5+2,"yyyymmdd")&"-"&4,'Policy Register'!$O:$O,0)),"") | D28: =IFERROR(INDEX('Policy Register'!$E:$E,MATCH(TEXT(A5+2,"yyyymmdd")&"-"&4,'Policy Register'!$O:$O,0)),"") | E28: =IFERROR(INDEX('Policy Register'!$F:$F,MATCH(TEXT(A5+2,"yyyymmdd")&"-"&4,'Policy Register'!$O:$O,0)),"") | F28: =IFERROR(INDEX('Policy Register'!$G:$G,MATCH(TEXT(A5+2,"yyyymmdd")&"-"&4,'Policy Register'!$O:$O,0)),"")
B30: ="📅 " & "THURSDAY" & " · " & TEXT(A5+3,"d mmm yyyy")
B31: =IF(COUNTIFS('Policy Register'!$F$5:$F$304,A5+3)=0,"No renewals scheduled.","")
B32: CLIENT | C32: CLASS | D32: DESCRIPTION | E32: DUE DATE | F32: STATUS
B33: =IFERROR(INDEX('Policy Register'!$C:$C,MATCH(TEXT(A5+3,"yyyymmdd")&"-"&1,'Policy Register'!$O:$O,0)),"") | C33: =IFERROR(INDEX('Policy Register'!$D:$D,MATCH(TEXT(A5+3,"yyyymmdd")&"-"&1,'Policy Register'!$O:$O,0)),"") | D33: =IFERROR(INDEX('Policy Register'!$E:$E,MATCH(TEXT(A5+3,"yyyymmdd")&"-"&1,'Policy Register'!$O:$O,0)),"") | E33: =IFERROR(INDEX('Policy Register'!$F:$F,MATCH(TEXT(A5+3,"yyyymmdd")&"-"&1,'Policy Register'!$O:$O,0)),"") | F33: =IFERROR(INDEX('Policy Register'!$G:$G,MATCH(TEXT(A5+3,"yyyymmdd")&"-"&1,'Policy Register'!$O:$O,0)),"")
B34: =IFERROR(INDEX('Policy Register'!$C:$C,MATCH(TEXT(A5+3,"yyyymmdd")&"-"&2,'Policy Register'!$O:$O,0)),"") | C34: =IFERROR(INDEX('Policy Register'!$D:$D,MATCH(TEXT(A5+3,"yyyymmdd")&"-"&2,'Policy Register'!$O:$O,0)),"") | D34: =IFERROR(INDEX('Policy Register'!$E:$E,MATCH(TEXT(A5+3,"yyyymmdd")&"-"&2,'Policy Register'!$O:$O,0)),"") | E34: =IFERROR(INDEX('Policy Register'!$F:$F,MATCH(TEXT(A5+3,"yyyymmdd")&"-"&2,'Policy Register'!$O:$O,0)),"") | F34: =IFERROR(INDEX('Policy Register'!$G:$G,MATCH(TEXT(A5+3,"yyyymmdd")&"-"&2,'Policy Register'!$O:$O,0)),"")
B35: =IFERROR(INDEX('Policy Register'!$C:$C,MATCH(TEXT(A5+3,"yyyymmdd")&"-"&3,'Policy Register'!$O:$O,0)),"") | C35: =IFERROR(INDEX('Policy Register'!$D:$D,MATCH(TEXT(A5+3,"yyyymmdd")&"-"&3,'Policy Register'!$O:$O,0)),"") | D35: =IFERROR(INDEX('Policy Register'!$E:$E,MATCH(TEXT(A5+3,"yyyymmdd")&"-"&3,'Policy Register'!$O:$O,0)),"") | E35: =IFERROR(INDEX('Policy Register'!$F:$F,MATCH(TEXT(A5+3,"yyyymmdd")&"-"&3,'Policy Register'!$O:$O,0)),"") | F35: =IFERROR(INDEX('Policy Register'!$G:$G,MATCH(TEXT(A5+3,"yyyymmdd")&"-"&3,'Policy Register'!$O:$O,0)),"")
B36: =IFERROR(INDEX('Policy Register'!$C:$C,MATCH(TEXT(A5+3,"yyyymmdd")&"-"&4,'Policy Register'!$O:$O,0)),"") | C36: =IFERROR(INDEX('Policy Register'!$D:$D,MATCH(TEXT(A5+3,"yyyymmdd")&"-"&4,'Policy Register'!$O:$O,0)),"") | D36: =IFERROR(INDEX('Policy Register'!$E:$E,MATCH(TEXT(A5+3,"yyyymmdd")&"-"&4,'Policy Register'!$O:$O,0)),"") | E36: =IFERROR(INDEX('Policy Register'!$F:$F,MATCH(TEXT(A5+3,"yyyymmdd")&"-"&4,'Policy Register'!$O:$O,0)),"") | F36: =IFERROR(INDEX('Policy Register'!$G:$G,MATCH(TEXT(A5+3,"yyyymmdd")&"-"&4,'Policy Register'!$O:$O,0)),"")
B38: ="📅 " & "FRIDAY" & " · " & TEXT(A5+4,"d mmm yyyy")
B39: =IF(COUNTIFS('Policy Register'!$F$5:$F$304,A5+4)=0,"No renewals scheduled.","")
B40: CLIENT | C40: CLASS | D40: DESCRIPTION | E40: DUE DATE | F40: STATUS
B41: =IFERROR(INDEX('Policy Register'!$C:$C,MATCH(TEXT(A5+4,"yyyymmdd")&"-"&1,'Policy Register'!$O:$O,0)),"") | C41: =IFERROR(INDEX('Policy Register'!$D:$D,MATCH(TEXT(A5+4,"yyyymmdd")&"-"&1,'Policy Register'!$O:$O,0)),"") | D41: =IFERROR(INDEX('Policy Register'!$E:$E,MATCH(TEXT(A5+4,"yyyymmdd")&"-"&1,'Policy Register'!$O:$O,0)),"") | E41: =IFERROR(INDEX('Policy Register'!$F:$F,MATCH(TEXT(A5+4,"yyyymmdd")&"-"&1,'Policy Register'!$O:$O,0)),"") | F41: =IFERROR(INDEX('Policy Register'!$G:$G,MATCH(TEXT(A5+4,"yyyymmdd")&"-"&1,'Policy Register'!$O:$O,0)),"")
B42: =IFERROR(INDEX('Policy Register'!$C:$C,MATCH(TEXT(A5+4,"yyyymmdd")&"-"&2,'Policy Register'!$O:$O,0)),"") | C42: =IFERROR(INDEX('Policy Register'!$D:$D,MATCH(TEXT(A5+4,"yyyymmdd")&"-"&2,'Policy Register'!$O:$O,0)),"") | D42: =IFERROR(INDEX('Policy Register'!$E:$E,MATCH(TEXT(A5+4,"yyyymmdd")&"-"&2,'Policy Register'!$O:$O,0)),"") | E42: =IFERROR(INDEX('Policy Register'!$F:$F,MATCH(TEXT(A5+4,"yyyymmdd")&"-"&2,'Policy Register'!$O:$O,0)),"") | F42: =IFERROR(INDEX('Policy Register'!$G:$G,MATCH(TEXT(A5+4,"yyyymmdd")&"-"&2,'Policy Register'!$O:$O,0)),"")
B43: =IFERROR(INDEX('Policy Register'!$C:$C,MATCH(TEXT(A5+4,"yyyymmdd")&"-"&3,'Policy Register'!$O:$O,0)),"") | C43: =IFERROR(INDEX('Policy Register'!$D:$D,MATCH(TEXT(A5+4,"yyyymmdd")&"-"&3,'Policy Register'!$O:$O,0)),"") | D43: =IFERROR(INDEX('Policy Register'!$E:$E,MATCH(TEXT(A5+4,"yyyymmdd")&"-"&3,'Policy Register'!$O:$O,0)),"") | E43: =IFERROR(INDEX('Policy Register'!$F:$F,MATCH(TEXT(A5+4,"yyyymmdd")&"-"&3,'Policy Register'!$O:$O,0)),"") | F43: =IFERROR(INDEX('Policy Register'!$G:$G,MATCH(TEXT(A5+4,"yyyymmdd")&"-"&3,'Policy Register'!$O:$O,0)),"")
B44: =IFERROR(INDEX('Policy Register'!$C:$C,MATCH(TEXT(A5+4,"yyyymmdd")&"-"&4,'Policy Register'!$O:$O,0)),"") | C44: =IFERROR(INDEX('Policy Register'!$D:$D,MATCH(TEXT(A5+4,"yyyymmdd")&"-"&4,'Policy Register'!$O:$O,0)),"") | D44: =IFERROR(INDEX('Policy Register'!$E:$E,MATCH(TEXT(A5+4,"yyyymmdd")&"-"&4,'Policy Register'!$O:$O,0)),"") | E44: =IFERROR(INDEX('Policy Register'!$F:$F,MATCH(TEXT(A5+4,"yyyymmdd")&"-"&4,'Policy Register'!$O:$O,0)),"") | F44: =IFERROR(INDEX('Policy Register'!$G:$G,MATCH(TEXT(A5+4,"yyyymmdd")&"-"&4,'Policy Register'!$O:$O,0)),"")
B46: ="📅 " & "SATURDAY" & " · " & TEXT(A5+5,"d mmm yyyy")
B47: =IF(COUNTIFS('Policy Register'!$F$5:$F$304,A5+5)=0,"No renewals scheduled.","")
...

Sheet Policy Register
A2: 📋 POLICY REGISTER — Single source of truth for every policy
A3: Enter policies from row 5 down · Insurance Class & Status use dropdowns · Days Overdue and Calendar sync run automatically
B4: POLICY ID | C4: CLIENT NAME | D4: INSURANCE CLASS | E4: DESCRIPTION | F4: DUE DATE | G4: STATUS | H4: DAYS OVERDUE | I4: NOTES | J4: CLIENT EMAIL | L4: UpRank | M4: OverdueRank | N4: DayRank | O4: DayKey | P4: LAST MILESTONE
B5: =IF(C5="","","POL-"&TEXT(ROW()-4,"0000")) | C5: Achieng Njeri | D5: Medical | E5: Family medical cover - Bronze Plan | F5: 46391 | G5: Renewed | H5: =IF(OR(G5="Renewed",G5=""),0,IF(TODAY()>F5,TODAY()-F5,0)) | I5: Renewed after reminder call | J5: achieng.n0@example.com | L5: =IF(AND(G5<>"Renewed",F5<>"",F5>=TODAY()),SUMPRODUCT(($G$5:$G$304<>"Renewed")*($F$5:$F$304<>"")*($F$5:$F$304>=TODAY())*($F$5:$F$304<F5))+SUMPRODUCT(($G$5:$G$304<>"Renewed")*($F$5:$F$304=F5)*(ROW($F$5:$F$304)<ROW(F5)))+1,"") | M5: =IF(H5>0,SUMPRODUCT(($H$5:$H$304>H5))+SUMPRODUCT(($H$5:$H$304=H5)*(ROW($H$5:$H$304)<ROW(H5)))+1,"") | N5: =IF(F5<>"",SUMPRODUCT(($F$5:$F$304=F5)*(ROW($F$5:$F$304)<ROW(F5)))+1,"") | O5: =IF(F5<>"",TEXT(F5,"yyyymmdd")&"-"&N5,"")
B6: =IF(C6="","","POL-"&TEXT(ROW()-4,"0000")) | C6: Grace Chepkoech | D6: WIBA | E6: WIBA - 60 employees | F6: 46281 | G6: Renewed | H6: =IF(OR(G6="Renewed",G6=""),0,IF(TODAY()>F6,TODAY()-F6,0)) | I6: Renewed via M-Pesa | J6: grace.c1@example.com | L6: =IF(AND(G6<>"Renewed",F6<>"",F6>=TODAY()),SUMPRODUCT(($G$5:$G$304<>"Renewed")*($F$5:$F$304<>"")*($F$5:$F$304>=TODAY())*($F$5:$F$304<F6))+SUMPRODUCT(($G$5:$G$304<>"Renewed")*($F$5:$F$304=F6)*(ROW($F$5:$F$304)<ROW(F6)))+1,"") | M6: =IF(H6>0,SUMPRODUCT(($H$5:$H$304>H6))+SUMPRODUCT(($H$5:$H$304=H6)*(ROW($H$5:$H$304)<ROW(H6)))+1,"") | N6: =IF(F6<>"",SUMPRODUCT(($F$5:$F$304=F6)*(ROW($F$5:$F$304)<ROW(F6)))+1,"") | O6: =IF(F6<>"",TEXT(F6,"yyyymmdd")&"-"&N6,"")
B7: =IF(C7="","","POL-"&TEXT(ROW()-4,"0000")) | C7: Naomi Nyaga | D7: Public Liability | E7: Public liability - restaurant | F7: 46256 | G7: Renewed | H7: =IF(OR(G7="Renewed",G7=""),0,IF(TODAY()>F7,TODAY()-F7,0)) | I7: Renewed via M-Pesa | J7: naomi.n2@example.com | L7: =IF(AND(G7<>"Renewed",F7<>"",F7>=TODAY()),SUMPRODUCT(($G$5:$G$304<>"Renewed")*($F$5:$F$304<>"")*($F$5:$F$304>=TODAY())*($F$5:$F$304<F7))+SUMPRODUCT(($G$5:$G$304<>"Renewed")*($F$5:$F$304=F7)*(ROW($F$5:$F$304)<ROW(F7)))+1,"") | M7: =IF(H7>0,SUMPRODUCT(($H$5:$H$304>H7))+SUMPRODUCT(($H$5:$H$304=H7)*(ROW($H$5:$H$304)<ROW(H7)))+1,"") | N7: =IF(F7<>"",SUMPRODUCT(($F$5:$F$304=F7)*(ROW($F$5:$F$304)<ROW(F7)))+1,"") | O7: =IF(F7<>"",TEXT(F7,"yyyymmdd")&"-"&N7,"")
B8: =IF(C8="","","POL-"&TEXT(ROW()-4,"0000")) | C8: Mercy Ndung'u | D8: Motor | E8: Comprehensive cover - Toyota Axio KDC 950E | F8: 46348 | G8: Not Renewed | H8: =IF(OR(G8="Renewed",G8=""),0,IF(TODAY()>F8,TODAY()-F8,0)) | J8: mercy.n3@example.com | L8: =IF(AND(G8<>"Renewed",F8<>"",F8>=TODAY()),SUMPRODUCT(($G$5:$G$304<>"Renewed")*($F$5:$F$304<>"")*($F$5:$F$304>=TODAY())*($F$5:$F$304<F8))+SUMPRODUCT(($G$5:$G$304<>"Renewed")*($F$5:$F$304=F8)*(ROW($F$5:$F$304)<ROW(F8)))+1,"") | M8: =IF(H8>0,SUMPRODUCT(($H$5:$H$304>H8))+SUMPRODUCT(($H$5:$H$304=H8)*(ROW($H$5:$H$304)<ROW(H8)))+1,"") | N8: =IF(F8<>"",SUMPRODUCT(($F$5:$F$304=F8)*(ROW($F$5:$F$304)<ROW(F8)))+1,"") | O8: =IF(F8<>"",TEXT(F8,"yyyymmdd")&"-"&N8,"")
B9: =IF(C9="","","POL-"&TEXT(ROW()-4,"0000")) | C9: Rift Valley Dairies | D9: Fire | E9: Fire & burglary - warehouse | F9: 46268 | G9: Renewed | H9: =IF(OR(G9="Renewed",G9=""),0,IF(TODAY()>F9,TODAY()-F9,0)) | I9: Renewed via M-Pesa | J9: rift.d4@example.com | L9: =IF(AND(G9<>"Renewed",F9<>"",F9>=TODAY()),SUMPRODUCT(($G$5:$G$304<>"Renewed")*($F$5:$F$304<>"")*($F$5:$F$304>=TODAY())*($F$5:$F$304<F9))+SUMPRODUCT(($G$5:$G$304<>"Renewed")*($F$5:$F$304=F9)*(ROW($F$5:$F$304)<ROW(F9)))+1,"") | M9: =IF(H9>0,SUMPRODUCT(($H$5:$H$304>H9))+SUMPRODUCT(($H$5:$H$304=H9)*(ROW($H$5:$H$304)<ROW(H9)))+1,"") | N9: =IF(F9<>"",SUMPRODUCT(($F$5:$F$304=F9)*(ROW($F$5:$F$304)<ROW(F9)))+1,"") | O9: =IF(F9<>"",TEXT(F9,"yyyymmdd")&"-"&N9,"")
B10: =IF(C10="","","POL-"&TEXT(ROW()-4,"0000")) | C10: Hassan Nyaga | D10: Medical | E10: Individual medical cover - Gold Plan | F10: 46261 | G10: Renewed | H10: =IF(OR(G10="Renewed",G10=""),0,IF(TODAY()>F10,TODAY()-F10,0)) | I10: Client renewed early | J10: hassan.n5@example.com | L10: =IF(AND(G10<>"Renewed",F10<>"",F10>=TODAY()),SUMPRODUCT(($G$5:$G$304<>"Renewed")*($F$5:$F$304<>"")*($F$5:$F$304>=TODAY())*($F$5:$F$304<F10))+SUMPRODUCT(($G$5:$G$304<>"Renewed")*($F$5:$F$304=F10)*(ROW($F$5:$F$304)<ROW(F10)))+1,"") | M10: =IF(H10>0,SUMPRODUCT(($H$5:$H$304>H10))+SUMPRODUCT(($H$5:$H$304=H10)*(ROW($H$5:$H$304)<ROW(H10)))+1,"") | N10: =IF(F10<>"",SUMPRODUCT(($F$5:$F$304=F10)*(ROW($F$5:$F$304)<ROW(F10)))+1,"") | O10: =IF(F10<>"",TEXT(F10,"yyyymmdd")&"-"&N10,"")
B11: =IF(C11="","","POL-"&TEXT(ROW()-4,"0000")) | C11: Abigail Njeri | D11: WIBA | E11: WIBA - 15 employees | F11: 46362 | G11: Not Renewed | H11: =IF(OR(G11="Renewed",G11=""),0,IF(TODAY()>F11,TODAY()-F11,0)) | J11: abigail.n6@example.com | L11: =IF(AND(G11<>"Renewed",F11<>"",F11>=TODAY()),SUMPRODUCT(($G$5:$G$304<>"Renewed")*($F$5:$F$304<>"")*($F$5:$F$304>=TODAY())*($F$5:$F$304<F11))+SUMPRODUCT(($G$5:$G$304<>"Renewed")*($F$5:$F$304=F11)*(ROW($F$5:$F$304)<ROW(F11)))+1,"") | M11: =IF(H11>0,SUMPRODUCT(($H$5:$H$304>H11))+SUMPRODUCT(($H$5:$H$304=H11)*(ROW($H$5:$H$304)<ROW(H11)))+1,"") | N11: =IF(F11<>"",SUMPRODUCT(($F$5:$F$304=F11)*(ROW($F$5:$F$304)<ROW(F11)))+1,"") | O11: =IF(F11<>"",TEXT(F11,"yyyymmdd")&"-"&N11,"")
B12: =IF(C12="","","POL-"&TEXT(ROW()-4,"0000")) | C12: Dennis Akinyi | D12: Motor | E12: Comprehensive cover - Subaru Forester KDB 803G | F12: 46307 | G12: Not Renewed | H12: =IF(OR(G12="Renewed",G12=""),0,IF(TODAY()>F12,TODAY()-F12,0)) | J12: dennis.a7@example.com | L12: =IF(AND(G12<>"Renewed",F12<>"",F12>=TODAY()),SUMPRODUCT(($G$5:$G$304<>"Renewed")*($F$5:$F$304<>"")*($F$5:$F$304>=TODAY())*($F$5:$F$304<F12))+SUMPRODUCT(($G$5:$G$304<>"Renewed")*($F$5:$F$304=F12)*(ROW($F$5:$F$304)<ROW(F12)))+1,"") | M12: =IF(H12>0,SUMPRODUCT(($H$5:$H$304>H12))+SUMPRODUCT(($H$5:$H$304=H12)*(ROW($H$5:$H$304)<ROW(H12)))+1,"") | N12: =IF(F12<>"",SUMPRODUCT(($F$5:$F$304=F12)*(ROW($F$5:$F$304)<ROW(F12)))+1,"") | O12: =IF(F12<>"",TEXT(F12,"yyyymmdd")&"-"&N12,"")
B13: =IF(C13="","","POL-"&TEXT(ROW()-4,"0000")) | C13: Victor Otieno | D13: Motor | E13: Comprehensive cover - Toyota Axio KDA 624E | F13: 46302 | G13: Not Renewed | H13: =IF(OR(G13="Renewed",G13=""),0,IF(TODAY()>F13,TODAY()-F13,0)) | J13: victor.o8@example.com | L13: =IF(AND(G13<>"Renewed",F13<>"",F13>=TODAY()),SUMPRODUCT(($G$5:$G$304<>"Renewed")*($F$5:$F$304<>"")*($F$5:$F$304>=TODAY())*($F$5:$F$304<F13))+SUMPRODUCT(($G$5:$G$304<>"Renewed")*($F$5:$F$304=F13)*(ROW($F$5:$F$304)<ROW(F13)))+1,"") | M13: =IF(H13>0,SUMPRODUCT(($H$5:$H$304>H13))+SUMPRODUCT(($H$5:$H$304=H13)*(ROW($H$5:$H$304)<ROW(H13)))+1,"") | N13: =IF(F13<>"",SUMPRODUCT(($F$5:$F$304=F13)*(ROW($F$5:$F$304)<ROW(F13)))+1,"") | O13: =IF(F13<>"",TEXT(F13,"yyyymmdd")&"-"&N13,"")
B14: =IF(C14="","","POL-"&TEXT(ROW()-4,"0000")) | C14: Joyce Karanja | D14: WIBA | E14: WIBA - 15 employees | F14: 46284 | G14: Not Renewed | H14: =IF(OR(G14="Renewed",G14=""),0,IF(TODAY()>F14,TODAY()-F14,0)) | I14: Left voicemail | J14: joyce.k9@example.com | L14: =IF(AND(G14<>"Renewed",F14<>"",F14>=TODAY()),SUMPRODUCT(($G$5:$G$304<>"Renewed")*($F$5:$F$304<>"")*($F$5:$F$304>=TODAY())*($F$5:$F$304<F14))+SUMPRODUCT(($G$5:$G$304<>"Renewed")*($F$5:$F$304=F14)*(ROW($F$5:$F$304)<ROW(F14)))+1,"") | M14: =IF(H14>0,SUMPRODUCT(($H$5:$H$304>H14))+SUMPRODUCT(($H$5:$H$304=H14)*(ROW($H$5:$H$304)<ROW(H14)))+1,"") | N14: =IF(F14<>"",SUMPRODUCT(($F$5:$F$304=F14)*(ROW($F$5:$F$304)<ROW(F14)))+1,"") | O14: =IF(F14<>"",TEXT(F14,"yyyymmdd")&"-"&N14,"")
B15: =IF(C15="","","POL-"&TEXT(ROW()-4,"0000")) | C15: Mwangi Hassan | D15: Motor | E15: Comprehensive cover - Mazda Demio KCZ 672K | F15: 46403 | G15: Not Renewed | H15: =IF(OR(G15="Renewed",G15=""),0,IF(TODAY()>F15,TODAY()-F15,0)) | J15: mwangi.h10@example.com | L15: =IF(AND(G15<>"Renewed",F15<>"",F15>=TODAY()),SUMPRODUCT(($G$5:$G$304<>"Renewed")*($F$5:$F$304<>"")*($F$5:$F$304>=TODAY())*($F$5:$F$304<F15))+SUMPRODUCT(($G$5:$G$304<>"Renewed")*($F$5:$F$304=F15)*(ROW($F$5:$F$304)<ROW(F15)))+1,"") | M15: =IF(H15>0,SUMPRODUCT(($H$5:$H$304>H15))+SUMPRODUCT(($H$5:$H$304=H15)*(ROW($H$5:$H$304)<ROW(H15)))+1,"") | N15: =IF(F15<>"",SUMPRODUCT(($F$5:$F$304=F15)*(ROW($F$5:$F$304)<ROW(F15)))+1,"") | O15: =IF(F15<>"",TEXT(F15,"yyyymmdd")&"-"&N15,"")
B16: =IF(C16="","","POL-"&TEXT(ROW()-4,"0000")) | C16: Mercy Wanjiru | D16: Motor | E16: Third party only - Isuzu D-Max KCZ 556D | F16: 46306 | G16: Renewed | H16: =IF(OR(G16="Renewed",G16=""),0,IF(TODAY()>F16,TODAY()-F16,0)) | I16: Renewed via bank transfer | J16: mercy.w11@example.com | L16: =IF(AND(G16<>"Renewed",F16<>"",F16>=TODAY()),SUMPRODUCT(($G$5:$G$304<>"Renewed")*($F$5:$F$304<>"")*($F$5:$F$304>=TODAY())*($F$5:$F$304<F16))+SUMPRODUCT(($G$5:$G$304<>"Renewed")*($F$5:$F$304=F16)*(ROW($F$5:$F$304)<ROW(F16)))+1,"") | M16: =IF(H16>0,SUMPRODUCT(($H$5:$H$304>H16))+SUMPRODUCT(($H$5:$H$304=H16)*(ROW($H$5:$H$304)<ROW(H16)))+1,"") | N16: =IF(F16<>"",SUMPRODUCT(($F$5:$F$304=F16)*(ROW($F$5:$F$304)<ROW(F16)))+1,"") | O16: =IF(F16<>"",TEXT(F16,"yyyymmdd")&"-"&N16,"")
B17: =IF(C17="","","POL-"&TEXT(ROW()-4,"0000")) | C17: Ruth Omondi | D17: Motor | E17: Comprehensive cover - Toyota Axio KDC 241H | F17: 46318 | G17: Not Renewed | H17: =IF(OR(G17="Renewed",G17=""),0,IF(TODAY()>F17,TODAY()-F17,0)) | J17: ruth.o12@example.com | L17: =IF(AND(G17<>"Renewed",F17<>"",F17>=TODAY()),SUMPRODUCT(($G$5:$G$304<>"Renewed")*($F$5:$F$304<>"")*($F$5:$F$304>=TODAY())*($F$5:$F$304<F17))+SUMPRODUCT(($G$5:$G$304<>"Renewed")*($F$5:$F$304=F17)*(ROW($F$5:$F$304)<ROW(F17)))+1,"") | M17: =IF(H17>0,SUMPRODUCT(($H$5:$H$304>H17))+SUMPRODUCT(($H$5:$H$304=H17)*(ROW($H$5:$H$304)<ROW(H17)))+1,"") | N17: =IF(F17<>"",SUMPRODUCT(($F$5:$F$304=F17)*(ROW($F$5:$F$304)<ROW(F17)))+1,"") | O17: =IF(F17<>"",TEXT(F17,"yyyymmdd")&"-"&N17,"")
B18: =IF(C18="","","POL-"&TEXT(ROW()-4,"0000")) | C18: Chebet Mbugua | D18: Fire | E18: Fire & burglary - warehouse | F18: 46289 | G18: Renewed | H18: =IF(OR(G18="Renewed",G18=""),0,IF(TODAY()>F18,TODAY()-F18,0)) | I18: Client renewed early | J18: chebet.m13@example.com | L18: =IF(AND(G18<>"Renewed",F18<>"",F18>=TODAY()),SUMPRODUCT(($G$5:$G$304<>"Renewed")*($F$5:$F$304<>"")*($F$5:$F$304>=TODAY())*($F$5:$F$304<F18))+SUMPRODUCT(($G$5:$G$304<>"Renewed")*($F$5:$F$304=F18)*(ROW($F$5:$F$304)<ROW(F18)))+1,"") | M18: =IF(H18>0,SUMPRODUCT(($H$5:$H$304>H18))+SUMPRODUCT(($H$5:$H$304=H18)*(ROW($H$5:$H$304)<ROW(H18)))+1,"") | N18: =IF(F18<>"",SUMPRODUCT(($F$5:$F$304=F18)*(ROW($F$5:$F$304)<ROW(F18)))+1,"") | O18: =IF(F18<>"",TEXT(F18,"yyyymmdd")&"-"&N18,"")
B19: =IF(C19="","","POL-"&TEXT(ROW()-4,"0000")) | C19: Savannah Logistics Ltd | D19: Medical | E19: Group medical - 12 staff | F19: 46404 | G19: Not Renewed | H19: =IF(OR(G19="Renewed",G19=""),0,IF(TODAY()>F19,TODAY()-F19,0)) | J19: savannah.l14@example.com | L19: =IF(AND(G19<>"Renewed",F19<>"",F19>=TODAY()),SUMPRODUCT(($G$5:$G$304<>"Renewed")*($F$5:$F$304<>"")*($F$5:$F$304>=TODAY())*($F$5:$F$304<F19))+SUMPRODUCT(($G$5:$G$304<>"Renewed")*($F$5:$F$304=F19)*(ROW($F$5:$F$304)<ROW(F19)))+1,"") | M19: =IF(H19>0,SUMPRODUCT(($H$5:$H$304>H19))+SUMPRODUCT(($H$5:$H$304=H19)*(ROW($H$5:$H$304)<ROW(H19)))+1,"") | N19: =IF(F19<>"",SUMPRODUCT(($F$5:$F$304=F19)*(ROW($F$5:$F$304)<ROW(F19)))+1,"") | O19: =IF(F19<>"",TEXT(F19,"yyyymmdd")&"-"&N19,"")
B20: =IF(C20="","","POL-"&TEXT(ROW()-4,"0000")) | C20: Grace Nyaga | D20: Public Liability | E20: Public liability - restaurant | F20: 46317 | G20: Not Renewed | H20: =IF(OR(G20="Renewed",G20=""),0,IF(TODAY()>F20,TODAY()-F20,0)) | J20: grace.n15@example.com | L20: =IF(AND(G20<>"Renewed",F20<>"",F20>=TODAY()),SUMPRODUCT(($G$5:$G$304<>"Renewed")*($F$5:$F$304<>"")*($F$5:$F$304>=TODAY())*($F$5:$F$304<F20))+SUMPRODUCT(($G$5:$G$304<>"Renewed")*($F$5:$F$304=F20)*(ROW($F$5:$F$304)<ROW(F20)))+1,"") | M20: =IF(H20>0,SUMPRODUCT(($H$5:$H$304>H20))+SUMPRODUCT(($H$5:$H$304=H20)*(ROW($H$5:$H$304)<ROW(H20)))+1,"") | N20: =IF(F20<>"",SUMPRODUCT(($F$5:$F$304=F20)*(ROW($F$5:$F$304)<ROW(F20)))+1,"") | O20: =IF(F20<>"",TEXT(F20,"yyyymmdd")&"-"&N20,"")
B21: =IF(C21="","","POL-"&TEXT(ROW()-4,"0000")) | C21: Linet Njeri | D21: Motor | E21: Comprehensive cover - Toyota Axio KCZ 659F | F21: 46314 | G21: Not Renewed | H21: =IF(OR(G21="Renewed",G21=""),0,IF(TODAY()>F21,TODAY()-F21,0)) | J21: linet.n16@example.com | L21: =IF(AND(G21<>"Renewed",F21<>"",F21>=TODAY()),SUMPRODUCT(($G$5:$G$304<>"Renewed")*($F$5:$F$304<>"")*($F$5:$F$304>=TODAY())*($F$5:$F$304<F21))+SUMPRODUCT(($G$5:$G$304<>"Renewed")*($F$5:$F$304=F21)*(ROW($F$5:$F$304)<ROW(F21)))+1,"") | M21: =IF(H21>0,SUMPRODUCT(($H$5:$H$304>H21))+SUMPRODUCT(($H$5:$H$304=H21)*(ROW($H$5:$H$304)<ROW(H21)))+1,"") | N21: =IF(F21<>"",SUMPRODUCT(($F$5:$F$304=F21)*(ROW($F$5:$F$304)<ROW(F21)))+1,"") | O21: =IF(F21<>"",TEXT(F21,"yyyymmdd")&"-"&N21,"")
B22: =IF(C22="","","POL-"&TEXT(ROW()-4,"0000")) | C22: Mwangi Njeri | D22: WIBA | E22: WIBA - 60 employees | F22: 46313 | G22: Not Renewed | H22: =IF(OR(G22="Renewed",G22=""),0,IF(TODAY()>F22,TODAY()-F22,0)) | J22: mwangi.n17@example.com | L22: =IF(AND(G22<>"Renewed",F22<>"",F22>=TODAY()),SUMPRODUCT(($G$5:$G$304<>"Renewed")*($F$5:$F$304<>"")*($F$5:$F$304>=TODAY())*($F$5:$F$304<F22))+SUMPRODUCT(($G$5:$G$304<>"Renewed")*($F$5:$F$304=F22)*(ROW($F$5:$F$304)<ROW(F22)))+1,"") | M22: =IF(H22>0,SUMPRODUCT(($H$5:$H$304>H22))+SUMPRODUCT(($H$5:$H$304=H22)*(ROW($H$5:$H$304)<ROW(H22)))+1,"") | N22: =IF(F22<>"",SUMPRODUCT(($F$5:$F$304=F22)*(ROW($F$5:$F$304)<ROW(F22)))+1,"") | O22: =IF(F22<>"",TEXT(F22,"yyyymmdd")&"-"&N22,"")
B23: =IF(C23="","","POL-"&TEXT(ROW()-4,"0000")) | C23: Amina Karanja | D23: WIBA | E23: WIBA - 25 employees | F23: 46316 | G23: Not Renewed | H23: =IF(OR(G23="Renewed",G23=""),0,IF(TODAY()>F23,TODAY()-F23,0)) | J23: amina.k18@example.com | L23: =IF(AND(G23<>"Renewed",F23<>"",F23>=TODAY()),SUMPRODUCT(($G$5:$G$304<>"Renewed")*($F$5:$F$304<>"")*($F$5:$F$304>=TODAY())*($F$5:$F$304<F23))+SUMPRODUCT(($G$5:$G$304<>"Renewed")*($F$5:$F$304=F23)*(ROW($F$5:$F$304)<ROW(F23)))+1,"") | M23: =IF(H23>0,SUMPRODUCT(($H$5:$H$304>H23))+SUMPRODUCT(($H$5:$H$304=H23)*(ROW($H$5:$H$304)<ROW(H23)))+1,"") | N23: =IF(F23<>"",SUMPRODUCT(($F$5:$F$304=F23)*(ROW($F$5:$F$304)<ROW(F23)))+1,"") | O23: =IF(F23<>"",TEXT(F23,"yyyymmdd")&"-"&N23,"")
B24: =IF(C24="","","POL-"&TEXT(ROW()-4,"0000")) | C24: Felix Adhiambo | D24: Medical | E24: Family medical cover - Silver Plan | F24: 46266 | G24: Renewed | H24: =IF(OR(G24="Renewed",G24=""),0,IF(TODAY()>F24,TODAY()-F24,0)) | I24: Client renewed early | J24: felix.a19@example.com | L24: =IF(AND(G24<>"Renewed",F24<>"",F24>=TODAY()),SUMPRODUCT(($G$5:$G$304<>"Renewed")*($F$5:$F$304<>"")*($F$5:$F$304>=TODAY())*($F$5:$F$304<F24))+SUMPRODUCT(($G$5:$G$304<>"Renewed")*($F$5:$F$304=F24)*(ROW($F$5:$F$304)<ROW(F24)))+1,"") | M24: =IF(H24>0,SUMPRODUCT(($H$5:$H$304>H24))+SUMPRODUCT(($H$5:$H$304=H24)*(ROW($H$5:$H$304)<ROW(H24)))+1,"") | N24: =IF(F24<>"",SUMPRODUCT(($F$5:$F$304=F24)*(ROW($F$5:$F$304)<ROW(F24)))+1,"") | O24: =IF(F24<>"",TEXT(F24,"yyyymmdd")&"-"&N24,"")
B25: =IF(C25="","","POL-"&TEXT(ROW()-4,"0000")) | C25: Kilimani Pharmacy | D25: Public Liability | E25: Public liability - restaurant | F25: 46263 | G25: Renewed | H25: =IF(OR(G25="Renewed",G25=""),0,IF(TODAY()>F25,TODAY()-F25,0)) | I25: Renewed, certificate sent | J25: kilimani.p20@example.com | L25: =IF(AND(G25<>"Renewed",F25<>"",F25>=TODAY()),SUMPRODUCT(($G$5:$G$304<>"Renewed")*($F$5:$F$304<>"")*($F$5:$F$304>=TODAY())*($F$5:$F$304<F25))+SUMPRODUCT(($G$5:$G$304<>"Renewed")*($F$5:$F$304=F25)*(ROW($F$5:$F$304)<ROW(F25)))+1,"") | M25: =IF(H25>0,SUMPRODUCT(($H$5:$H$304>H25))+SUMPRODUCT(($H$5:$H$304=H25)*(ROW($H$5:$H$304)<ROW(H25)))+1,"") | N25: =IF(F25<>"",SUMPRODUCT(($F$5:$F$304=F25)*(ROW($F$5:$F$304)<ROW(F25)))+1,"") | O25: =IF(F25<>"",TEXT(F25,"yyyymmdd")&"-"&N25,"")
B26: =IF(C26="","","POL-"&TEXT(ROW()-4,"0000")) | C26: Mwangi Wafula | D26: Medical | E26: Family medical cover - Bronze Plan | F26: 46305 | G26: Not Renewed | H26: =IF(OR(G26="Renewed",G26=""),0,IF(TODAY()>F26,TODAY()-F26,0)) | J26: mwangi.w21@example.com | L26: =IF(AND(G26<>"Renewed",F26<>"",F26>=TODAY()),SUMPRODUCT(($G$5:$G$304<>"Renewed")*($F$5:$F$304<>"")*($F$5:$F$304>=TODAY())*($F$5:$F$304<F26))+SUMPRODUCT(($G$5:$G$304<>"Renewed")*($F$5:$F$304=F26)*(ROW($F$5:$F$304)<ROW(F26)))+1,"") | M26: =IF(H26>0,SUMPRODUCT(($H$5:$H$304>H26))+SUMPRODUCT(($H$5:$H$304=H26)*(ROW($H$5:$H$304)<ROW(H26)))+1,"") | N26: =IF(F26<>"",SUMPRODUCT(($F$5:$F$304=F26)*(ROW($F$5:$F$304)<ROW(F26)))+1,"") | O26: =IF(F26<>"",TEXT(F26,"yyyymmdd")&"-"&N26,"")
B27: =IF(C27="","","POL-"&TEXT(ROW()-4,"0000")) | C27: Amina Mbugua | D27: WIBA | E27: WIBA - 25 employees | F27: 46288 | G27: Renewed | H27: =IF(OR(G27="Renewed",G27=""),0,IF(TODAY()>F27,TODAY()-F27,0)) | I27: Renewed, certificate sent | J27: amina.m22@example.com | L27: =IF(AND(G27<>"Renewed",F27<>"",F27>=TODAY()),SUMPRODUCT(($G$5:$G$304<>"Renewed")*($F$5:$F$304<>"")*($F$5:$F$304>=TODAY())*($F$5:$F$304<F27))+SUMPRODUCT(($G$5:$G$304<>"Renewed")*($F$5:$F$304=F27)*(ROW($F$5:$F$304)<ROW(F27)))+1,"") | M27: =IF(H27>0,SUMPRODUCT(($H$5:$H$304>H27))+SUMPRODUCT(($H$5:$H$304=H27)*(ROW($H$5:$H$304)<ROW(H27)))+1,"") | N27: =IF(F27<>"",SUMPRODUCT(($F$5:$F$304=F27)*(ROW($F$5:$F$304)<ROW(F27)))+1,"") | O27: =IF(F27<>"",TEXT(F27,"yyyymmdd")&"-"&N27,"")
B28: =IF(C28="","","POL-"&TEXT(ROW()-4,"0000")) | C28: Collins Wanjiru | D28: Motor | E28: Comprehensive cover - Subaru Forester KDA 609K | F28: 46273 | G28: Not Renewed | H28: =IF(OR(G28="Renewed",G28=""),0,IF(TODAY()>F28,TODAY()-F28,0)) | I28: Client requested revised quote | J28: collins.w23@example.com | L28: =IF(AND(G28<>"Renewed",F28<>"",F28>=TODAY()),SUMPRODUCT(($G$5:$G$304<>"Renewed")*($F$5:$F$304<>"")*($F$5:$F$304>=TODAY())*($F$5:$F$304<F28))+SUMPRODUCT(($G$5:$G$304<>"Renewed")*($F$5:$F$304=F28)*(ROW($F$5:$F$304)<ROW(F28)))+1,"") | M28: =IF(H28>0,SUMPRODUCT(($H$5:$H$304>H28))+SUMPRODUCT(($H$5:$H$304=H28)*(ROW($H$5:$H$304)<ROW(H28)))+1,"") | N28: =IF(F28<>"",SUMPRODUCT(($F$5:$F$304=F28)*(ROW($F$5:$F$304)<ROW(F28)))+1,"") | O28: =IF(F28<>"",TEXT(F28,"yyyymmdd")&"-"&N28,"")
B29: =IF(C29="","","POL-"&TEXT(ROW()-4,"0000")) | C29: Grace Muriuki | D29: Motor | E29: Comprehensive cover - Mazda Demio KDB 630C | F29: 46295 | G29: Renewed | H29: =IF(OR(G29="Renewed",G29=""),0,IF(TODAY()>F29,TODAY()-F29,0)) | I29: Renewed, certificate sent | J29: grace.m24@example.com | L29: =IF(AND(G29<>"Renewed",F29<>"",F29>=TODAY()),SUMPRODUCT(($G$5:$G$304<>"Renewed")*($F$5:$F$304<>"")*($F$5:$F$304>=TODAY())*($F$5:$F$304<F29))+SUMPRODUCT(($G$5:$G$304<>"Renewed")*($F$5:$F$304=F29)*(ROW($F$5:$F$304)<ROW(F29)))+1,"") | M29: =IF(H29>0,SUMPRODUCT(($H$5:$H$304>H29))+SUMPRODUCT(($H$5:$H$304=H29)*(ROW($H$5:$H$304)<ROW(H29)))+1,"") | N29: =IF(F29<>"",SUMPRODUCT(($F$5:$F$304=F29)*(ROW($F$5:$F$304)<ROW(F29)))+1,"") | O29: =IF(F29<>"",TEXT(F29,"yyyymmdd")&"-"&N29,"")
B30: =IF(C30="","","POL-"&TEXT(ROW()-4,"0000")) | C30: Esther Barasa | D30: Motor | E30: Third party only - Isuzu D-Max KCZ 781E | F30: 46338 | G30: Not Renewed | H30: =IF(OR(G30="Renewed",G30=""),0,IF(TODAY()>F30,TODAY()-F30,0)) | J30: esther.b25@example.com | L30: =IF(AND(G30<>"Renewed",F30<>"",F30>=TODAY()),SUMPRODUCT(($G$5:$G$304<>"Renewed")*($F$5:$F$304<>"")*($F$5:$F$304>=TODAY())*($F$5:$F$304<F30))+SUMPRODUCT(($G$5:$G$304<>"Renewed")*($F$5:$F$304=F30)*(ROW($F$5:$F$304)<ROW(F30)))+1,"") | M30: =IF(H30>0,SUMPRODUCT(($H$5:$H$304>H30))+SUMPRODUCT(($H$5:$H$304=H30)*(ROW($H$5:$H$304)<ROW(H30)))+1,"") | N30: =IF(F30<>"",SUMPRODUCT(($F$5:$F$304=F30)*(ROW($F$5:$F$304)<ROW(F30)))+1,"") | O30: =IF(F30<>"",TEXT(F30,"yyyymmdd")&"-"&N30,"")
B31: =IF(C31="","","POL-"&TEXT(ROW()-4,"0000")) | C31: Achieng Akinyi | D31: Motor | E31: Comprehensive cover - Honda Fit KDB 697F | F31: 46323 | G31: Not Renewed | H31: =IF(OR(G31="Renewed",G31=""),0,IF(TODAY()>F31,TODAY()-F31,0)) | J31: achieng.a26@example.com | L31: =IF(AND(G31<>"Renewed",F31<>"",F31>=TODAY()),SUMPRODUCT(($G$5:$G$304<>"Renewed")*($F$5:$F$304<>"")*($F$5:$F$304>=TODAY())*($F$5:$F$304<F31))+SUMPRODUCT(($G$5:$G$304<>"Renewed")*($F$5:$F$304=F31)*(ROW($F$5:$F$304)<ROW(F31)))+1,"") | M31: =IF(H31>0,SUMPRODUCT(($H$5:$H$304>H31))+SUMPRODUCT(($H$5:$H$304=H31)*(ROW($H$5:$H$304)<ROW(H31)))+1,"") | N31: =IF(F31<>"",SUMPRODUCT(($F$5:$F$304=F31)*(ROW($F$5:$F$304)<ROW(F31)))+1,"") | O31: =IF(F31<>"",TEXT(F31,"yyyymmdd")&"-"&N31,"")
B32: =IF(C32="","","POL-"&TEXT(ROW()-4,"0000")) | C32: Nyota Schools Ltd | D32: WIBA | E32: WIBA - 25 employees | F32: 46352 | G32: Not Renewed | H32: =IF(OR(G32="Renewed",G32=""),0,IF(TODAY()>F32,TODAY()-F32,0)) | J32: nyota.l27@example.com | L32: =IF(AND(G32<>"Renewed",F32<>"",F32>=TODAY()),SUMPRODUCT(($G$5:$G$304<>"Renewed")*($F$5:$F$304<>"")*($F$5:$F$304>=TODAY())*($F$5:$F$304<F32))+SUMPRODUCT(($G$5:$G$304<>"Renewed")*($F$5:$F$304=F32)*(ROW($F$5:$F$304)<ROW(F32)))+1,"") | M32: =IF(H32>0,SUMPRODUCT(($H$5:$H$304>H32))+SUMPRODUCT(($H$5:$H$304=H32)*(ROW($H$5:$H$304)<ROW(H32)))+1,"") | N32: =IF(F32<>"",SUMPRODUCT(($F$5:$F$304=F32)*(ROW($F$5:$F$304)<ROW(F32)))+1,"") | O32: =IF(F32<>"",TEXT(F32,"yyyymmdd")&"-"&N32,"")
B33: =IF(C33="","","POL-"&TEXT(ROW()-4,"0000")) | C33: Joyce Mutua | D33: Motor | E33: Comprehensive cover - Honda Fit KCZ 381D | F33: 46322 | G33: Not Renewed | H33: =IF(OR(G33="Renewed",G33=""),0,IF(TODAY()>F33,TODAY()-F33,0)) | J33: joyce.m28@example.com | L33: =IF(AND(G33<>"Renewed",F33<>"",F33>=TODAY()),SUMPRODUCT(($G$5:$G$304<>"Renewed")*($F$5:$F$304<>"")*($F$5:$F$304>=TODAY())*($F$5:$F$304<F33))+SUMPRODUCT(($G$5:$G$304<>"Renewed")*($F$5:$F$304=F33)*(ROW($F$5:$F$304)<ROW(F33)))+1,"") | M33: =IF(H33>0,SUMPRODUCT(($H$5:$H$304>H33))+SUMPRODUCT(($H$5:$H$304=H33)*(ROW($H$5:$H$304)<ROW(H33)))+1,"") | N33: =IF(F33<>"",SUMPRODUCT(($F$5:$F$304=F33)*(ROW($F$5:$F$304)<ROW(F33)))+1,"") | O33: =IF(F33<>"",TEXT(F33,"yyyymmdd")&"-"&N33,"")
B34: =IF(C34="","","POL-"&TEXT(ROW()-4,"0000")) | C34: Ruth Barasa | D34: Public Liability | E34: Public liability - construction site | F34: 46283 | G34: Not Renewed | H34: =IF(OR(G34="Renewed",G34=""),0,IF(TODAY()>F34,TODAY()-F34,0)) | J34: ruth.b29@example.com | L34: =IF(AND(G34<>"Renewed",F34<>"",F34>=TODAY()),SUMPRODUCT(($G$5:$G$304<>"Renewed")*($F$5:$F$304<>"")*($F$5:$F$304>=TODAY())*($F$5:$F$304<F34))+SUMPRODUCT(($G$5:$G$304<>"Renewed")*($F$5:$F$304=F34)*(ROW($F$5:$F$304)<ROW(F34)))+1,"") | M34: =IF(H34>0,SUMPRODUCT(($H$5:$H$304>H34))+SUMPRODUCT(($H$5:$H$304=H34)*(ROW($H$5:$H$304)<ROW(H34)))+1,"") | N34: =IF(F34<>"",SUMPRODUCT(($F$5:$F$304=F34)*(ROW($F$5:$F$304)<ROW(F34)))+1,"") | O34: =IF(F34<>"",TEXT(F34,"yyyymmdd")&"-"&N34,"")
B35: =IF(C35="","","POL-"&TEXT(ROW()-4,"0000")) | C35: Amina Otieno | D35: Motor | E35: Commercial vehicle - Canter lorry KDA 794E | F35: 46367 | G35: Not Renewed | H35: =IF(OR(G35="Renewed",G35=""),0,IF(TODAY()>F35,TODAY()-F35,0)) | J35: amina.o30@example.com | L35: =IF(AND(G35<>"Renewed",F35<>"",F35>=TODAY()),SUMPRODUCT(($G$5:$G$304<>"Renewed")*($F$5:$F$304<>"")*($F$5:$F$304>=TODAY())*($F$5:$F$304<F35))+SUMPRODUCT(($G$5:$G$304<>"Renewed")*($F$5:$F$304=F35)*(ROW($F$5:$F$304)<ROW(F35)))+1,"") | M35: =IF(H35>0,SUMPRODUCT(($H$5:$H$304>H35))+SUMPRODUCT(($H$5:$H$304=H35)*(ROW($H$5:$H$304)<ROW(H35)))+1,"") | N35: =IF(F35<>"",SUMPRODUCT(($F$5:$F$304=F35)*(ROW($F$5:$F$304)<ROW(F35)))+1,"") | O35: =IF(F35<>"",TEXT(F35,"yyyymmdd")&"-"&N35,"")
B36: =IF(C36="","","POL-"&TEXT(ROW()-4,"0000")) | C36: Abigail Wanjiru | D36: Public Liability | E36: Public liability - school premises | F36: 46316 | G36: Not Renewed | H36: =IF(OR(G36="Renewed",G36=""),0,IF(TODAY()>F36,TODAY()-F36,0)) | J36: abigail.w31@example.com | L36: =IF(AND(G36<>"Renewed",F36<>"",F36>=TODAY()),SUMPRODUCT(($G$5:$G$304<>"Renewed")*($F$5:$F$304<>"")*($F$5:$F$304>=TODAY())*($F$5:$F$304<F36))+SUMPRODUCT(($G$5:$G$304<>"Renewed")*($F$5:$F$304=F36)*(ROW($F$5:$F$304)<ROW(F36)))+1,"") | M36: =IF(H36>0,SUMPRODUCT(($H$5:$H$304>H36))+SUMPRODUCT(($H$5:$H$304=H36)*(ROW($H$5:$H$304)<ROW(H36)))+1,"") | N36: =IF(F36<>"",SUMPRODUCT(($F$5:$F$304=F36)*(ROW($F$5:$F$304)<ROW(F36)))+1,"") | O36: =IF(F36<>"",TEXT(F36,"yyyymmdd")&"-"&N36,"")
B37: =IF(C37="","","POL-"&TEXT(ROW()-4,"0000")) | C37: Zuri Interiors | D37: Motor | E37: Comprehensive cover - Mazda Demio KDA 744B | F37: 46317 | G37: Not Renewed | H37: =IF(OR(G37="Renewed",G37=""),0,IF(TODAY()>F37,TODAY()-F37,0)) | J37: zuri.i32@example.com | L37: =IF(AND(G37<>"Renewed",F37<>"",F37>=TODAY()),SUMPRODUCT(($G$5:$G$304<>"Renewed")*($F$5:$F$304<>"")*($F$5:$F$304>=TODAY())*($F$5:$F$304<F37))+SUMPRODUCT(($G$5:$G$304<>"Renewed")*($F$5:$F$304=F37)*(ROW($F$5:$F$304)<ROW(F37)))+1,"") | M37: =IF(H37>0,SUMPRODUCT(($H$5:$H$304>H37))+SUMPRODUCT(($H$5:$H$304=H37)*(ROW($H$5:$H$304)<ROW(H37)))+1,"") | N37: =IF(F37<>"",SUMPRODUCT(($F$5:$F$304=F37)*(ROW($F$5:$F$304)<ROW(F37)))+1,"") | O37: =IF(F37<>"",TEXT(F37,"yyyymmdd")&"-"&N37,"")
B38: =IF(C38="","","POL-"&TEXT(ROW()-4,"0000")) | C38: Wanjiku Muriuki | D38: Motor | E38: Comprehensive cover - Subaru Forester KDB 304H | F38: 46305 | G38: Not Renewed | H38: =IF(OR(G38="Renewed",G38=""),0,IF(TODAY()>F38,TODAY()-F38,0)) | J38: wanjiku.m33@example.com | L38: =IF(AND(G38<>"Renewed",F38<>"",F38>=TODAY()),SUMPRODUCT(($G$5:$G$304<>"Renewed")*($F$5:$F$304<>"")*($F$5:$F$304>=TODAY())*($F$5:$F$304<F38))+SUMPRODUCT(($G$5:$G$304<>"Renewed")*($F$5:$F$304=F38)*(ROW($F$5:$F$304)<ROW(F38)))+1,"") | M38: =IF(H38>0,SUMPRODUCT(($H$5:$H$304>H38))+SUMPRODUCT(($H$5:$H$304=H38)*(ROW($H$5:$H$304)<ROW(H38)))+1,"") | N38: =IF(F38<>"",SUMPRODUCT(($F$5:$F$304=F38)*(ROW($F$5:$F$304)<ROW(F38)))+1,"") | O38: =IF(F38<>"",TEXT(F38,"yyyymmdd")&"-"&N38,"")
B39: =IF(C39="","","POL-"&TEXT(ROW()-4,"0000")) | C39: Achieng Barasa | D39: Fire | E39: Fire & burglary - retail shop | F39: 46273 | G39: Not Renewed | H39: =IF(OR(G39="Renewed",G39=""),0,IF(TODAY()>F39,TODAY()-F39,0)) | I39: Awaiting payment confirmation | J39: achieng.b34@example.com | L39: =IF(AND(G39<>"Renewed",F39<>"",F39>=TODAY()),SUMPRODUCT(($G$5:$G$304<>"Renewed")*($F$5:$F$304<>"")*($F$5:$F$304>=TODAY())*($F$5:$F$304<F39))+SUMPRODUCT(($G$5:$G$304<>"Renewed")*($F$5:$F$304=F39)*(ROW($F$5:$F$304)<ROW(F39)))+1,"") | M39: =IF(H39>0,SUMPRODUCT(($H$5:$H$304>H39))+SUMPRODUCT(($H$5:$H$304=H39)*(ROW($H$5:$H$304)<ROW(H39)))+1,"") | N39: =IF(F39<>"",SUMPRODUCT(($F$5:$F$304=F39)*(ROW($F$5:$F$304)<ROW(F39)))+1,"") | O39: =IF(F39<>"",TEXT(F39,"yyyymmdd")&"-"&N39,"")
B40: =IF(C40="","","POL-"&TEXT(ROW()-4,"0000")) | C40: Achieng Muriuki | D40: Fire | E40: Fire & burglary - warehouse | F40: 46347 | G40: Not Renewed | H40: =IF(OR(G40="Renewed",G40=""),0,IF(TODAY()>F40,TODAY()-F40,0)) | J40: achieng.m35@example.com | L40: =IF(AND(G40<>"Renewed",F40<>"",F40>=TODAY()),SUMPRODUCT(($G$5:$G$304<>"Renewed")*($F$5:$F$304<>"")*($F$5:$F$304>=TODAY())*($F$5:$F$304<F40))+SUMPRODUCT(($G$5:$G$304<>"Renewed")*($F$5:$F$304=F40)*(ROW($F$5:$F$304)<ROW(F40)))+1,"") | M40: =IF(H40>0,SUMPRODUCT(($H$5:$H$304>H40))+SUMPRODUCT(($H$5:$H$304=H40)*(ROW($H$5:$H$304)<ROW(H40)))+1,"") | N40: =IF(F40<>"",SUMPRODUCT(($F$5:$F$304=F40)*(ROW($F$5:$F$304)<ROW(F40)))+1,"") | O40: =IF(F40<>"",TEXT(F40,"yyyymmdd")&"-"&N40,"")
B41: =IF(C41="","","POL-"&TEXT(ROW()-4,"0000")) | C41: Dennis Hassan | D41: Medical | E41: Family medical cover - Bronze Plan | F41: 46270 | G41: Renewed | H41: =IF(OR(G41="Renewed",G41=""),0,IF(TODAY()>F41,TODAY()-F41,0)) | I41: Renewed via bank transfer | J41: dennis.h36@example.com | L41: =IF(AND(G41<>"Renewed",F41<>"",F41>=TODAY()),SUMPRODUCT(($G$5:$G$304<>"Renewed")*($F$5:$F$304<>"")*($F$5:$F$304>=TODAY())*($F$5:$F$304<F41))+SUMPRODUCT(($G$5:$G$304<>"Renewed")*($F$5:$F$304=F41)*(ROW($F$5:$F$304)<ROW(F41)))+1,"") | M41: =IF(H41>0,SUMPRODUCT(($H$5:$H$304>H41))+SUMPRODUCT(($H$5:$H$304=H41)*(ROW($H$5:$H$304)<ROW(H41)))+1,"") | N41: =IF(F41<>"",SUMPRODUCT(($F$5:$F$304=F41)*(ROW($F$5:$F$304)<ROW(F41)))+1,"") | O41: =IF(F41<>"",TEXT(F41,"yyyymmdd")&"-"&N41,"")
...

Sheet Activity Log
A2: 📝 ACTIVITY LOG — Automated record of every renewal action
A3: Written automatically by the tracker · Do not edit manually
B4: TIMESTAMP | C4: POLICY ID | D4: ACTION | E4: NOTES

Sheet Setup Guide
A2: ⚙️ SETUP GUIDE — Get your tracker running in five minutes
A3: Complete every step below once. After that, everything runs automatically.
B5: 1 | C5: Make a copy | D5: File → Make a copy, and save it to your own Google Drive.
B6: 2 | C6: Open Apps Script | D6: Extensions → Apps Script. A new code editor tab will open.
B7: 3 | C7: Delete the default code | D7: Select everything in the editor (Ctrl+A) and delete it.
B8: 4 | C8: Paste Code.gs | D8: Copy the full script from the Apps Script Backup sheet and paste it in.
B9: 5 | C9: Save | D9: Press Ctrl+S, or click the save icon in the Apps Script editor.
B10: 6 | C10: Authorize permissions | D10: Run setupDailyTrigger() once. Google will ask you to authorize Calendar and Gmail access — accept it.
B11: 7 | C11: Start using the tracker | D11: Add policies in the Policy Register sheet. Calendar events, dashboards and email reminders update automatically.
A13: 🏷️ HOW URGENCY COLOURS WORK
C14: Renewed | D14: Soft gold background, dark gold text — policy is complete.
C15: Not Renewed | D15: Soft burgundy background — still needs action.
C16: Due within 30 days | D16: Soft gold highlight on the due date.
C17: Due within 14 days | D17: Soft burnt-orange highlight.
C18: Due within 7 days | D18: Deeper burnt-orange highlight.
C19: Due today | D19: Dark chocolate background, white bold text.
C20: Overdue | D20: Deep burgundy background, white bold text.
A22: ⏰ TRIGGER SCHEDULE
C23: Calendar Sync | D23: Daily, 8:00am by default — plus instantly as you edit a policy. Keeps every renewal date on your Google Calendar.
C24: Daily Digest | D24: Daily, 8:00am by default — one short glance: due today, overdue count, next 5 coming up. To your team inbox.
C25: Weekly Summary | D25: Monday, 8:00am by default — fuller list: everything due in the next 30 days + full overdue list. To your team inbox.
C26: Milestone Alert | D26: Checked daily, 8:00am by default — client-facing renewal nudge. Fires once per policy at 60/30/14/7/3/1/0 days out, never repeated.
C28: Adjusting the times | D28: All four run at 8am out of the box. To change any of them (e.g. for testing), edit the TRIGGER_TIMES constant near the top of the script, then re-run setupDailyTrigger().
C29: Testing without waiting | D29: Run testDailyDigest(), testWeeklySummary(), or testMilestoneCheck() directly from the Apps Script editor (▶) to preview an email immediately.
C30: Team inbox | D30: Before running setupDailyTrigger(), set the TEAM_INBOX constant near the top of the script to your shared inbox — or leave it blank to use your own Google account.
C31: Dates going back a day? | D31: The date-shifting bug is fixed in v5.1, but only once this exact code is pasted into Extensions → Apps Script (having it in this backup tab is not enough). After pasting: run normalizeAllDueDates() once from the ▶ menu to force-fix every row already on the sheet and confirm it worked.

Sheet Apps Script Backup
A2: 💻 APPS SCRIPT v5.1 — Copy everything below into Extensions → Apps Script
A3: Select all text from B6 onward, copy, paste into the Apps Script editor, save, then run setupDailyTrigger()
B6: // ══════════════════════════════════════════════════════════════════
B7: // INSURANCE POLICY RENEWAL TRACKER PRO — Apps Script v4.0
B8: // Your Brokerage Name
B9: // Paste into Extensions → Apps Script → Save → Run setupDailyTrigger()
B10: // ══════════════════════════════════════════════════════════════════
B12: const SHEET_NAME = 'Policy Register';
B13: const LOG_SHEET = 'Activity Log';
B14: const CAL_NAME = 'Insurance Renewal Tracker';
B15: const FIRST_ROW = 5;
B16: const LAST_ROW = 304;
B18: // Where the Daily Digest and Weekly Summary land. Leave blank to use
B19: // whichever Google account runs the script.
... B572: }
